────────────────────── YChaos, The resilience testing framework ──────────────────────

                     YChaos CLI configuration                     
┏━━━━━━━━━━━━━━━┳━━━━━━━━━━━━━━━━━━━━━━━━━━━━━━━━━━━━━━━━━━━━━━━━┓
┃ Configuration ┃ Value                                          ┃
┡━━━━━━━━━━━━━━━╇━━━━━━━━━━━━━━━━━━━━━━━━━━━━━━━━━━━━━━━━━━━━━━━━┩
│ _command_     │ ychaos ➡ testplan ➡ validate                   │
│ config        │ prod                                           │
│ html_report   │ None                                           │
│ paths         │ tests/resources/testplans/valid                │
│               │ tests/resources/testplans/valid/testplan4.json │
│               │ tests/resources/testplans/invalid              │
│ text_report   │ docs/examples/text_report_example.txt          │
│ verbose       │ 0                                              │
└───────────────┴────────────────────────────────────────────────┘

[17:42:30] Starting app                                                    main.py:152
           Getting Test plans                                           validate.py:80
           Validating Test plans                                        validate.py:91


❗ tests/resources/testplans/invalid/testplan1.yaml
╭───────────── Validation Error ──────────────╮
│ 1 validation error for TestPlan             │
│ verification -> 0 -> type                   │
│   field required (type=value_error.missing) │
╰─────────────────────────────────────────────╯

✅ tests/resources/testplans/valid/testplan1.json
✅ tests/resources/testplans/valid/testplan1.yaml
✅ tests/resources/testplans/valid/testplan2.yaml
🔍 tests/resources/testplans/valid/testplan4.json not found

           Exiting with exitcode=1                                         main.py:236
───────────────────────────────────────── ☀ ──────────────────────────────────────────
